Workbook

Sheet Base Artigos
A1: ID | B1: Classificação | C1: Ano | D1: Autores | E1: Título | F1: Jounal | G1: SJR | H1: Citações | I1: País Aplicação | J1: País Autor Principal | K1: Abordagem Primpária | L1: Abordagem Secundária | M1: Plataforma de Resolução | N1: Objetivo Primário | O1: Objetivo Secundário | P1: Etapa da Cadeia Produtiva | Q1: Nível de Decisão | R1: DOI | S1: Link | T1: Palavras-chave autor
A2: 1 | B2: A | C2: 2019 | D2: Aguayo M.M.; Sarin S.C.; Cundiff J.S. | E2: A branch-and-price approach for a biomass feedstock logistics supply chain design problem | F2: IISE Transactions | G2: 0.862 | H2: 12 | I2: Estados Unidos | J2: Chile | K2: MILP | M2: CPLEX | N2: Min-C | O2: AGR, INST | P2: AGR, EST | Q2: TA | R2: 10.1080/24725854.2019.1589656 | S2: https://www.scopus.com/inward/record.uri?eid=2-s2.0-85066629282&doi=10.1080%2f24725854.2019.1589656&partnerID=40&md5=5698914ef7199ea4133fce1b173a01eb | T2: biomass logistics; branch-and-price; Cellulosic ethanol; facility location; lot-sizing
A3: 2 | B3: A | C3: 2023 | D3: Al Mohamed A.A.; Al Mohamed S.; Ahmad M. | E3: Solving aggregate production planning problem with uncertainty using fuzzy goal programming | F3: International Journal of Mathematics in Operational Research | G3: 0.272 | H3: 1 | I3: Síria | J3: Síria | K3: GP | L3: FL | M3: GAMS | N3: Min-C, Min-MO | O3: ARM, IND | P3: IND | Q3: TA | R3: 10.1504/IJMOR.2023.132838 | S3: https://www.scopus.com/inward/record.uri?eid=2-s2.0-85170406640&doi=10.1504%2fIJMOR.2023.132838&partnerID=40&md5=4912897a496be357a18091b25c770ea4 | T3: aggregate production planning; APP; FGP; fuzzy goal programming; fuzzy logic; goal programming; plastic industry
A4: 3 | B4: A | C4: 2021 | D4: Aliano Filho A.; Melo T.; Pato M.V. | E4: A bi-objective mathematical model for integrated planning of sugarcane harvesting and transport operations | F4: Computers and Operations Research | G4: 1.574 | H4: 13 | I4: Brasil | J4: Brasil | K4: MINLP | L4: MO | M4: JUMP/CPLEX | N4: Min-C, Min-T-AGR | O4: AGR | P4: AGR | Q4: TA | R4: 10.1016/j.cor.2021.105419 | S4: https://www.scopus.com/inward/record.uri?eid=2-s2.0-85107960409&doi=10.1016%2fj.cor.2021.105419&partnerID=40&md5=382589458131fe6684852de077af5cfd | T4: Integrated sugarcane harvesting and transport planning; Mixed-integer programming; Multi-objective optimization
A5: 4 | B5: A | C5: 2013 | D5: Awudu I.; Zhang J. | E5: Stochastic production planning for a biofuel supply chain under demand and price uncertainties | F5: Applied Energy | G5: 2.82 | H5: 122 | I5: Estados Unidos | J5: Estados Unidos | K5: SLP | M5: GAMS/MATLAB | N5: Max-LR | P5: AGR, IND, COM | Q5: TA | R5: 10.1016/j.apenergy.2012.09.025 | S5: https://www.scopus.com/inward/record.uri?eid=2-s2.0-84871810249&doi=10.1016%2fj.apenergy.2012.09.025&partnerID=40&md5=3a247c6286068a38cbf82e1f58a32fb1 | T5: Benders decomposition; Biofuel supply chain; Monte Carlo simulation; Stochastic programming
A6: 5 | B6: A | C6: 2009 | D6: Corsano G.; Aguirre P.A.; Montagna J.M. | E6: Multiperiod design and planning of multiproduct batch plants with mixed-product campaigns | F6: AIChE Journal | G6: 0.734 | H6: 5 | I6: Não Especificado | J6: Argentina | K6: MINLP | M6: GAMS | N6: Max-LR | P6: AGR, IND, EST | Q6: OP | R6: 10.1002/aic.11854 | S6: https://www.scopus.com/inward/record.uri?eid=2-s2.0-69049087107&doi=10.1002%2faic.11854&partnerID=40&md5=6c168665ffab8ee6df64f27a1f74debf | T6: Batch plant design; MINLP; Mixed-product campaigns; Multiperiod model; Production planning
A7: 6 | B7: A | C7: 2014 | D7: Corsano G.; Fumero Y.; Montagna J.M. | E7: Integrated decision making for the optimal bioethanol supply chain | F7: Energy Conversion and Management | G7: 2.553 | H7: 10 | I7: Não Especificado | J7: Argentina | K7: MILP | M7: GAMS | N7: Max-LR | P7: AGR, IND, EST | Q7: OP | R7: 10.1016/j.enconman.2014.04.090 | S7: https://www.scopus.com/inward/record.uri?eid=2-s2.0-84910075619&doi=10.1016%2fj.enconman.2014.04.090&partnerID=40&md5=a1d95054598a77fc254a92826334e881 | T7: Bioethanol production; Plant design; Production planning; Supply chain
A8: 7 | B8: A | C8: 2014 | D8: da Silva A.F.; Marins F.A.S. | E8: A Fuzzy Goal Programming model for solving aggregate production-planning problems under uncertainty: A case study in a Brazilian sugar mill | F8: Energy Economics | G8: 3.555 | H8: 50 | I8: Brasil | J8: Brasil | K8: GP | L8: FL | M8: GAMS/CPLEX | N8: Min-C, Max-P | O8: AGR, ARM, IND, MP, COM | P8: AGR, IND, COM | Q8: TA | R8: 10.1016/j.eneco.2014.07.005 | S8: https://www.scopus.com/inward/record.uri?eid=2-s2.0-84907853897&doi=10.1016%2fj.eneco.2014.07.005&partnerID=40&md5=b6cb58527aec159e6fa6e141369652a7 | T8: Aggregate production planning; Fuzzy goal programming; Goal programming; Sugar and ethanol mills
A9: 8 | B9: A | C9: 2013 | D9: Silva A.F. da; Marins F.A.S.; Barra Montevechi J.A. | E9: Multi-choice mixed integer goal programming optimization for real problems in a sugar and ethanol milling company | F9: Applied Mathematical Modelling | G9: 1 | H9: 40 | I9: Brasil | J9: Brasil | K9: GP | L9: MCMI | M9: GAMS/CPLEX | N9: Min-C, Max-P | O9: AGR, ARM, IND, MP | P9: AGR, IND | Q9: TA | R9: 10.1016/j.apm.2012.12.022 | S9: https://www.scopus.com/inward/record.uri?eid=2-s2.0-84875377451&doi=10.1016%2fj.apm.2012.12.022&partnerID=40&md5=f02fcec187df51170ecc27315df73f1b | T9: Aggregate production planning; Goal programming; Multi- Choice mixed integer goal programming; Multi-choice aspiration levels; Sugar and ethanol mills
A10: 9 | B10: A | C10: 2017 | D10: de Ávila Ribeiro Junqueira R.; Morabito R. | E10: Optimization approaches for sugarcane harvest front programming and scheduling | F10: Gestao e Producao | G10: 0.2 | H10: 16 | I10: Brasil | J10: Brasil | K10: MILP | M10: GAMS/CPLEX | N10: Min-C, Max-P, Min-T-AGR | O10: AGR | P10: AGR | Q10: OP | R10: 10.1590/0104-530X1882-16 | S10: https://www.scopus.com/inward/record.uri?eid=2-s2.0-85025139132&doi=10.1590%2f0104-530X1882-16&partnerID=40&md5=db90ddf501543c3f83096068037a53e3 | T10: Lot sizing and scheduling; Mixed integer programming; Programming and scheduling of harvest fronts; Sugarcane harvesting planning
A11: 10 | B11: A | C11: 2018 | D11: de Ávila Ribeiro Junqueira R.; Morabito R. | E11: Programming and scheduling sugarcane harvesting fronts: Model and solution methods for large-scale problems | F11: Gestao e Producao | G11: 0.2 | H11: 4 | I11: Brasil | J11: Brasil | K11: MILP | M11: GAMS/CPLEX | N11: Min-C | O11: AGR | P11: AGR | Q11: OP | R11: 10.1590/0104-530X2647-16 | S11: https://www.scopus.com/inward/record.uri?eid=2-s2.0-85045447528&doi=10.1590%2f0104-530X2647-16&partnerID=40&md5=b5fd1133a34f9a34589e2d5ffaafcd40 | T11: Mixed integer programming; Production lot sizing and scheduling; Relax-and-fix and fix-and-optimize heuristics; Sugarcane harvest programming
A12: 11 | B12: A | C12: 2019 | D12: de Ávila Ribeiro Junqueira R.; Morabito R. | E12: Modeling and solving a sugarcane harvest front scheduling problem | F12: International Journal of Production Economics | G12: 3.074 | H12: 40 | I12: Brasil | J12: Brasil | K12: MILP | M12: GAMS/CPLEX | N12: Min-C | O12: AGR | P12: AGR | Q12: TA | R12: 10.1016/j.ijpe.2019.03.009 | S12: https://www.scopus.com/inward/record.uri?eid=2-s2.0-85063589946&doi=10.1016%2fj.ijpe.2019.03.009&partnerID=40&md5=a12806fadb0be0553f1b9d0e75d81354 | T12: Case study; Logistics scheduling; Optimization approach; Sugarcane harvest front; Sugarmills; Validation process
A13: 12 | B13: A | C13: 2009 | D13: de Paiva R.P.O.; Morabito R. | E13: An optimization model for the aggregate production planning of a Brazilian sugar and ethanol milling company | F13: Annals of Operations Research | G13: 1.019 | H13: 51 | I13: Brasil | J13: Brasil | K13: MILP | M13: GAMS/CPLEX | N13: Max-LR | P13: AGR, IND | Q13: OP | R13: 10.1007/s10479-008-0428-9 | S13: https://www.scopus.com/inward/record.uri?eid=2-s2.0-64149125605&doi=10.1007%2fs10479-008-0428-9&partnerID=40&md5=7548dd3f373362d52f20ba43531f8c91 | T13: Aggregate production planning; Mixed integer optimization; Process selection; Production lot-sizing; Sugar and ethanol mills
A14: 13 | B14: A | C14: 2011 | D14: de Paiva R.P.O.; Morabito R. | E14: Stochastic robust optimization model applied to the aggregate production planning in mill cooperative socities in the sugar-energy sector | F14: Gestao e Producao | G14: 0.2 | H14: 6 | I14: Brasil | J14: Brasil | K14: SLP | L14: RO | M14: GAMS/CPLEX | N14: Max-LR | P14: IND, COM | Q14: TA, ES | R14: 10.1590/S0104-530X2011000400004 | S14: https://www.scopus.com/inward/record.uri?eid=2-s2.0-84856675703&doi=10.1590%2fS0104-530X2011000400004&partnerID=40&md5=199c3b71d25f358c30aa00b77d1f6dbb | T14: Aggregate production planning; Hierarchical planning; Stochastic robust programming; Sugarcane mills; Uncertainty analysis
A15: 14 | B15: A | C15: 2013 | D15: de Paiva R.P.O.; Morabito R. | E15: Optimization of the hierarchical production planning of a cooperative society of sugarcane milling companies; [Otimização do planejamento hierárquico da produção em usinas cooperadas do setor sucroenergético] | F15: Production | G15: 0.352 | H15: 4 | I15: Brasil | J15: Brasil | K15: MILP | M15: GAMS/CPLEX | N15: Max-LR | P15: IND, COM | Q15: TA, ES | R15: 10.1590/S0103-65132012005000077 | S15: https://www.scopus.com/inward/record.uri?eid=2-s2.0-84886552472&doi=10.1590%2fS0103-65132012005000077&partnerID=40&md5=f5b753a9bd3304102bb0cd8145474047 | T15: Aggregate production planning; Hierarchical planning; Mixed integer linear optimization; Sugarcane mills
A16: 15 | B16: A | C16: 2014 | D16: de Paiva R.P.O.; Morabito R. | E16: Hierarchical production planning for sugarcane milling companies: Robust optimization model; [Planejamento hierárquico da produção em usinas de açúcar e álcool: Modelagem de otimização robusta] | F16: Production | G16: 0.352 | H16: 3 | I16: Brasil | J16: Brasil | K16: MILP | L16: RO | M16: GAMS/CPLEX | N16: Max-LR | P16: AGR, IND | Q16: TA | R16: 10.1590/S0103-65132013005000032 | S16: https://www.scopus.com/inward/record.uri?eid=2-s2.0-84905180400&doi=10.1590%2fS0103-65132013005000032&partnerID=40&md5=11fdc50c66ee89ce72213dd34c6ce6ec | T16: Aggregate production planning; Hierarchical production planning; Mixed integer linear programming; Robust optimization; Sugarcane mills; Uncertainty analysis
A17: 16 | B17: A | C17: 2023 | D17: de Paiva R.P.O.; Rocco C.D.; Morabito R. | E17: A hierarchical supply chain model for the sugar–alcohol energy sector with robust optimization analysis | F17: International Transactions in Operational Research | G17: 1.027 | H17: 4 | I17: Brasil | J17: Brasil | K17: MILP | L17: RO | M17: CPLEX | N17: Max-LR | P17: AGR, IND | Q17: TA, ES | R17: 10.1111/itor.12909 | S17: https://www.scopus.com/inward/record.uri?eid=2-s2.0-85096878415&doi=10.1111%2fitor.12909&partnerID=40&md5=f838f5685e6d8194fa58d6a2b2db6313 | T17: hierarchical production planning; mixed-integer programming; robust optimization; sucroenergetic agroindustry; sugarcane; supply chain planning
A18: 17 | B18: A | C18: 2024 | D18: Hafezi N.; Sheikhdavoodi M.J.; Bahrami H.; Alavi S.E. | E18: Optimization of Harvesting Priority of Sugarcane Farms by the Generalized Assignment Problem | F18: Sugar Tech | G18: 0.451 | H18: 0 | I18: Irã | J18: Irã | K18: MILP | L18: FL | M18: GAMS/CPLEX | N18: Max-P | O18: AGR | P18: AGR | Q18: TA | R18: 10.1007/s12355-023-01336-2 | S18: https://www.scopus.com/inward/record.uri?eid=2-s2.0-85180642228&doi=10.1007%2fs12355-023-01336-2&partnerID=40&md5=613bd353d7aa58e5ca53c386c2cee26f | T18: Harvesting time optimization; Mixed integer programming; Neuro-fuzzy inference system; Sugarcane
A19: 18 | B19: A | C19: 2015 | D19: Kantas A.B.; Cobuloglu H.I.; Büyüktahtakn I.E. | E19: Multi-source capacitated lot-sizing for economically viable and clean biofuel production | F19: Journal of Cleaner Production | G19: 2.058 | H19: 26 | I19: Estados Unidos | J19: Estados Unidos | K19: MILP | M19: ILOG/CPLEX | N19: Min-C, Min-IA | O19: ARM, MP, INST | P19: AGR, IND | Q19: TA | R19: 10.1016/j.jclepro.2015.02.001 | S19: https://www.scopus.com/inward/record.uri?eid=2-s2.0-84928768228&doi=10.1016%2fj.jclepro.2015.02.001&partnerID=40&md5=15fc26072e55b1570a5109d825726e84 | T19: Biofuel; CO2 emissions; Mixed-integer; optimization; Production planning; Sustainability; Water usage
A20: 19 | B20: A | C20: 2020 | D20: Li X.; Jin X.; Lu S.; Li Z.; Wang Y.; Cao J. | E20: Carbon-efficient production scheduling of a bioethanol plant considering diversified feedstock pelletization density: A case study | F20: Processes | G20: 0.525 | H20: 1 | I20: China | J20: China | K20: MILP | L20: MO | M20: LINGO | N20: Max-LR, Min-IA | P20: AGR, IND | Q20: OP | R20: 10.3390/PR8091189 | S20: https://www.scopus.com/inward/record.uri?eid=2-s2.0-85092094522&doi=10.3390%2fPR8091189&partnerID=40&md5=6ff1f4447942e7ccc373334ed5fdcc3a | T20: Bioethanol plant; Carbon emission; Dual-objective optimization; Scheduling
A21: 20 | B21: A | C21: 2022 | D21: Li X.; Lu S.; Li Z.; Wang Y.; Zhu L. | E21: Modeling and optimization of bioethanol production planning under hybrid uncertainty: A heuristic multi-stage stochastic programming approach | F21: Energy | G21: 2.11 | H21: 12 | I21: China | J21: China | K21: SLP | M21: LINGO/MATLAB | N21: Min-C | O21: ARM, IND, MP, COM | P21: AGR, IND, COM | Q21: OP | R21: 10.1016/j.energy.2022.123285 | S21: https://www.scopus.com/inward/record.uri?eid=2-s2.0-85123736368&doi=10.1016%2fj.energy.2022.123285&partnerID=40&md5=da6cbcda171e6fa9f327c8263bf3d580 | T21: Bioethanol plant; Heuristic decomposition; Hybrid uncertainty; Mixed multi-stage optimization; Production planning
A22: 21 | B22: A | C22: 2021 | D22: Poltroniere S.C.; Aliano Filho A.; Caversan A.S.; Balbo A.R.; Florentino H.D.O. | E22: Integrated planning for planting and harvesting sugarcane and energy-cane for the production of sucrose and energy | F22: Computers and Electronics in Agriculture | G22: 1.735 | H22: 14 | I22: Brasil | J22: Brasil | K22: MILP | M22: JUMP/CPLEX | N22: Max-P | O22: AGR | P22: AGR | Q22: TA | R22: 10.1016/j.compag.2020.105956 | S22: https://www.scopus.com/inward/record.uri?eid=2-s2.0-85102558107&doi=10.1016%2fj.compag.2020.105956&partnerID=40&md5=e341dc723c32bf132c339236564e6513 | T22: Energy-cane; Fix-and-optimize; Mathematical optimization; Relax-and-fix; Sugarcane
A23: 22 | B23: A | C23: 2019 | D23: Saadati M.; Hosseininezhad S.J. | E23: Designing a hub location model in a bagasse-based bioethanol supply chain network in Iran (case study: Iran sugar industry) | F23: Biomass and Bioenergy | G23: 1.107 | H23: 20 | I23: Irã | J23: Irã | K23: MILP | L23: MO | M23: GAMS/CPLEX | N23: Min-C, Min-IA | O23: AGR, ARM, IND, MP, INST | P23: EST | Q23: TA, ES | R23: 10.1016/j.biombioe.2019.01.013 | S23: https://www.scopus.com/inward/record.uri?eid=2-s2.0-85061054948&doi=10.1016%2fj.biombioe.2019.01.013&partnerID=40&md5=41d1fc458d170af3a2034fb3fc7fc0de | T23: Bagasse; Bagasse-based bio-ethanol; Hub location model; Second-generation bioethanol
A24: 23 | B24: A | C24: 2012 | D24: You F.; Tao L.; Graziano D.J.; Snyder S.W. | E24: Optimal design of sustainable cellulosic biofuel supply chains: Multiobjective optimization coupled with life cycle assessment and input-output analysis | F24: AIChE Journal | G24: 0.734 | H24: 602 | I24: Estados Unidos | J24: Estados Unidos | K24: MILP | L24: MO | M24: GAMS/CPLEX | N24: Min-C, Min-IA, Max-EMP | O24: AGR, ARM, IND, INST, COM | P24: AGR, IND, COM, EST | Q24: TA | R24: 10.1002/aic.12637 | S24: https://www.scopus.com/inward/record.uri?eid=2-s2.0-80052359753&doi=10.1002%2faic.12637&partnerID=40&md5=5750c8e9fda0ae83c38a59510192ad22 | T24: Biofuel supply chain; Input-output analysis; Life cycle analysis; Multiobjective optimization; Planning; Sustainability
B25: B *C | C25: 2017 | D25: Albernas-Carvajal Y.; Corsano G.; González Cortés M.; González Suárez E. | E25: Preliminary design for simultaneous saccharification and fermentation stages for ethanol production from sugar cane bagasse | F25: Chemical Engineering Research and Design | H25: 7 | R25: 10.1016/j.cherd.2017.08.029 | S25: https://www.scopus.com/inward/record.uri?eid=2-s2.0-85031717429&doi=10.1016%2fj.cherd.2017.08.029&partnerID=40&md5=b214c5ecc34cc49226d1c1ac8c3b086a | T25: Batch design; Lignocellulosic ethanol; Optimization; Simultaneous saccharification and fermentation
B26: B *C | C26: 2015 | D26: Bhargava A.K.; Singh S.R.; Bansal D. | E26: Production planning using fuzzy meta-goal programming model | F26: Indian Journal of Science and Technology | H26: 3 | R26: 10.17485/ijst/2015/v8i34/70706 | S26: https://www.scopus.com/inward/record.uri?eid=2-s2.0-85000788450&doi=10.17485%2fijst%2f2015%2fv8i34%2f70706&partnerID=40&md5=2f30ba6813f122828ee598fd5f54d614 | T26: Fuzzy goal programming; Fuzzy meta-goal programming method; Manufacturing plant; Meta goals; Production planning
B27: C | C27: 2020 | D27: Blanco A.M.; Susana Moreno M.; Taraborelli C.; D'Angelo F.; Iturmendi F.; Alberto Bandoni J. | E27: Model-based decision support tools at Jugos S.A. concentrated fruit juice plant | F27: INFORMS Journal on Applied Analytics | H27: 0 | R27: 10.1287/INTE.2020.1045 | S27: https://www.scopus.com/inward/record.uri?eid=2-s2.0-85093853011&doi=10.1287%2fINTE.2020.1045&partnerID=40&md5=86d41bb99a69ee5d66468e3374da9a95 | T27: Batch scheduling; Concentrated fruit juice; Decision making; Mixed-integer nonlinear programming; Production planning
B28: B *C | C28: 2019 | D28: Daraei M.; Avelin A.; Dotzauer E.; Thorin E. | E28: Evaluation of biofuel production integrated with existing CHP plants and the impacts on production planning of the system – A case study | F28: Applied Energy | H28: 8 | R28: 10.1016/j.apenergy.2019.113461 | S28: https://www.scopus.com/inward/record.uri?eid=2-s2.0-85067284871&doi=10.1016%2fj.apenergy.2019.113461&partnerID=40&md5=96cc4ade59bcab2e1b1269098411e77c | T28: Electric vehicles; Energy systems; Mixed Integer Linear Programming; Optimization; Straw-based bioethanol; Transportation sector
B29: C | C29: 2016 | D29: Goharimanesh M.; Lashkaripour A.; Akbari A.A. | E29: Optimization of biodiesel production using multi-objective genetic algorithm | F29: Journal of Applied Science and Engineering | H29: 4 | R29: 10.6180/jase.2016.19.2.02 | S29: https://www.scopus.com/inward/record.uri?eid=2-s2.0-84975760574&doi=10.6180%2fjase.2016.19.2.02&partnerID=40&md5=1425b1688ea9909484d3b9d7f8e8a2df | T29: Biodiesel; Fuel; Genetic algorithm; Methyl ester; Optimization; Triglycerides
B30: C | C30: 2013 | D30: Gonçalves L.A.; Filho R.M. | E30: Alcohol production process modelling based on indicators using transactional software, industrial automation and manufacturing execution systems-MES | F30: Chemical Engineering Transactions | H30: 2 | R30: 10.3303/CET1332222 | S30: https://www.scopus.com/inward/record.uri?eid=2-s2.0-84879229989&doi=10.3303%2fCET1332222&partnerID=40&md5=f03c097971ec344c671af2d300907faf | T30: 0
B31: B *C | C31: 2024 | D31: Machado R.L.; Abreu M.R. | E31: Multi-objective optimization of the first and second-generation ethanol supply chain in Brazil using the water-energy-food-land nexus approach | F31: Renewable and Sustainable Energy Reviews | H31: 0 | R31: 10.1016/j.rser.2024.114299 | S31: https://www.scopus.com/inward/record.uri?eid=2-s2.0-85184776077&doi=10.1016%2fj.rser.2024.114299&partnerID=40&md5=658d1df40adacfbbeb5e985afdb9147e | T31: Analytic hierarchy process; Biofuel supply chain; Ethanol; MILP; Sustainable development goal 7; Water-energy-food-land nexus
B32: C | C32: 2021 | D32: Plangsrisakul K.; Somboonwiwat T.; Khompatraporn C. | E32: Make-to-order production planning with seasonal supply in canned pineapple industry | F32: Proceedings - European Council for Modelling and Simulation, ECMS | H32: 0 | S32: https://www.scopus.com/inward/record.uri?eid=2-s2.0-85108187122&partnerID=40&md5=dcfb65c6e0e1a26d9a0e730c88f0cf33 | T32: Canned pineapple industry; Make-to-order inventory; Multi-products multi-periods production planning; Pineapple color ratios; Seasonal raw materials
B33: C | C33: 2020 | D33: Rogowska D. | E33: Vapour pressure of butanol as a component of gasoline; [Prężność par butanolu jako komponentu benzyn silnikowych] | F33: Nafta - Gaz | H33: 0 | R33: 10.18668/NG.2020.05.07 | S33: https://www.scopus.com/inward/record.uri?eid=2-s2.0-85118885278&doi=10.18668%2fNG.2020.05.07&partnerID=40&md5=ed5554e5861014ff590ab50bd9961aea | T33: Biobuthanol; E10 gasoline; Vapour pressure blending numbers
B34: C | C34: 2018 | D34: Salawu E.Y.; Ajayi O.O.; Inegbenebor A.; Afolalu S.A.; Samson O. | E34: Pareto analysis of product quality failures and cost effects in bottling machines-a lean thinking solution for alcohol industry | F34: International Journal of Mechanical Engineering and Technology | H34: 7 | S34: https://www.scopus.com/inward/record.uri?eid=2-s2.0-85060438668&partnerID=40&md5=40baab08168cb888852ba5905b7aa4e8 | T34: Bottling machines; Failures; Production; Reliability
B35: C | C35: 2010 | D35: Sharma P.K.; Romagnoli J. | E35: An integrated framework for enterprise management - A synergistic approach towards sustainable biorefineries | F35: 10AIChE - 2010 AIChE Spring Meeting and 6th Global Congress on Process Safety | H35: 0 | S35: https://www.scopus.com/inward/record.uri?eid=2-s2.0-77956004249&partnerID=40&md5=ebb5e6bb64ce9631d288b4fb18e71d7a | T35: 0
B36: B *C | C36: 2016 | D36: Sudtachat K. | E36: A two-stage stochastic programming model for districting and transportation lot-size of sugarcane | F36: Proceedings of the International Conference on Industrial Engineering and Operations Management | H36: 0 | S36: https://www.scopus.com/inward/record.uri?eid=2-s2.0-85018450227&partnerID=40&md5=7af5ccc8cca050211f5799503244a080 | T36: Districting problem; Lot sizing problem; Sugarcane; Two-stage stochastic programming model
B37: C | C37: 2006 | D37: Zimberg B.; Testuri C.E. | E37: Stochastic analysis of crude oil procurement and processing under uncertain demand for bunker fuel oil | F37: International Transactions in Operational Research | H37: 5 | R37: 10.1111/j.1475-3995.2006.00554.x | S37: https://www.scopus.com/inward/record.uri?eid=2-s2.0-63849134995&doi=10.1111%2fj.1475-3995.2006.00554.x&partnerID=40&md5=b658073b1c7d573894a924e1ab1dbefb | T37: Production planning; Stochastic programming

Sheet Exclusão de duplicados
A1: Título | B1: D - Duplicado
A2: A bi-objective mathematical model for integrated planning of sugarcane harvesting and transport operations | B2: D
A3: A Fuzzy Goal Programming model for solving aggregate production-planning problems under uncertainty: A case study in a Brazilian sugar mill | B3: D
A4: A hierarchical supply chain model for the sugar–alcohol energy sector with robust optimization analysis | B4: D
A5: Alcohol production process modelling based on indicators using transactional software, industrial automation and manufacturing execution systems-MES | B5: D
A6: An optimization model for the aggregate production planning of a Brazilian sugar and ethanol milling company | B6: D
A7: Carbon-efficient production scheduling of a bioethanol plant considering diversified feedstock pelletization density: A case study | B7: D
A8: Designing a hub location model in a bagasse-based bioethanol supply chain network in Iran (case study: Iran sugar industry) | B8: D
A9: Hybrid simulation framework for the production management of an ethanol biorefinery | B9: D
A10: Integrated decision making for the optimal bioethanol supply chain | B10: D
A11: Integrated planning for planting and harvesting sugarcane and energy-cane for the production of sucrose and energy | B11: D
A12: Multi-choice mixed integer goal programming optimization for real problems in a sugar and ethanol milling company | B12: D
... A19: Vapour pressure of butanol as a component of gasoline | B19: D
A20: An optimization model for the aggregate production planning in alcohol and sugar mills | B20: D | P20: 10.1590/s0104-530x2007000100004 | Q20: https://www.scopus.com/inward/record.uri?eid=2-s2.0-34547371168&doi=10.1590%2fs0104-530x2007000100004&partnerID=40&md5=27f18fb49bfbcfa7f8242dfa7066497e | R20: Aggregate production planning; Integer optimization; Lot-sizing; Process selection; Sugar and alcohol mills

Sheet Siglas
A1: Tipo | B1: Sigla | C1: Descrição
A2: Abordagem Primária | B2: MILP | C2: Mixed Integer Linear Programming
A3: Abordagem Primária | B3: MINLP | C3: Mixed Integer Non-Linear Programming
A4: Abordagem Primária | B4: GP | C4: Goal Programming
A5: Abordagem Primária | B5: SLP | C5: Stochastic Linear Programming
A6: Abordagem Secundária | B6: MO | C6: Multi-Objective
A7: Abordagem Secundária | B7: RO | C7: Robust Optimization
A8: Abordagem Secundária | B8: FL | C8: Fuzzy Logic
A9: Abordagem Secundária | B9: MCMI | C9: Multi-Choice Mixed Integer
A10: Plataforma Resolução | B10: GA | C10: GAMS
A11: Plataforma Resolução | B11: CP | C11: CPLEX
A12: Plataforma Resolução | B12: JU | C12: JUMP
... A35: Nível de decisão | B35: ES | C35: Estratégico

Sheet Publicações por ano
A1: Ano | B1: Publicações
A2: 2009 | B2: =COUNTIFS('Base Artigos'!$C$2:$C$24,'Publicações por ano'!A2) -> 2
A3: 2010 | B3: =COUNTIFS('Base Artigos'!$C$2:$C$24,'Publicações por ano'!A3) -> 0
A4: 2011 | B4: =COUNTIFS('Base Artigos'!$C$2:$C$24,'Publicações por ano'!A4) -> 1
A5: 2012 | B5: =COUNTIFS('Base Artigos'!$C$2:$C$24,'Publicações por ano'!A5) -> 1
A6: 2013 | B6: =COUNTIFS('Base Artigos'!$C$2:$C$24,'Publicações por ano'!A6) -> 3
A7: 2014 | B7: =COUNTIFS('Base Artigos'!$C$2:$C$24,'Publicações por ano'!A7) -> 3
A8: 2015 | B8: =COUNTIFS('Base Artigos'!$C$2:$C$24,'Publicações por ano'!A8) -> 1
A9: 2016 | B9: =COUNTIFS('Base Artigos'!$C$2:$C$24,'Publicações por ano'!A9) -> 0
A10: 2017 | B10: =COUNTIFS('Base Artigos'!$C$2:$C$24,'Publicações por ano'!A10) -> 1
A11: 2018 | B11: =COUNTIFS('Base Artigos'!$C$2:$C$24,'Publicações por ano'!A11) -> 1
A12: 2019 | B12: =COUNTIFS('Base Artigos'!$C$2:$C$24,'Publicações por ano'!A12) -> 3
A13: 2020 | B13: =COUNTIFS('Base Artigos'!$C$2:$C$24,'Publicações por ano'!A13) -> 1
... A17: 2024 | B17: =COUNTIFS('Base Artigos'!$C$2:$C$24,'Publicações por ano'!A17) -> 1

Sheet Publicações país pesquisadores
A1: País | B1: Coautores | C1: Autor principal
A2: Alemanha | B2: =COUNTIFS($A$18:$A$85,"Coautor",$C$18:$C$85,A2) -> 1 | C2: =COUNTIFS($A$18:$A$85,"Principal",$C$18:$C$85,A2) -> 0
A3: Portugal | B3: =COUNTIFS($A$18:$A$85,"Coautor",$C$18:$C$85,A3) -> 1 | C3: =COUNTIFS($A$18:$A$85,"Principal",$C$18:$C$85,A3) -> 0
A4: Jordânia | B4: =COUNTIFS($A$18:$A$85,"Coautor",$C$18:$C$85,A4) -> 1 | C4: =COUNTIFS($A$18:$A$85,"Principal",$C$18:$C$85,A4) -> 0
A5: Chile | B5: =COUNTIFS($A$18:$A$85,"Coautor",$C$18:$C$85,A5) -> 0 | C5: =COUNTIFS($A$18:$A$85,"Principal",$C$18:$C$85,A5) -> 1
A6: Síria | B6: =COUNTIFS($A$18:$A$85,"Coautor",$C$18:$C$85,A6) -> 1 | C6: =COUNTIFS($A$18:$A$85,"Principal",$C$18:$C$85,A6) -> 1
A7: Irã | B7: =COUNTIFS($A$18:$A$85,"Coautor",$C$18:$C$85,A7) -> 4 | C7: =COUNTIFS($A$18:$A$85,"Principal",$C$18:$C$85,A7) -> 2
A8: Argentina | B8: =COUNTIFS($A$18:$A$85,"Coautor",$C$18:$C$85,A8) -> 4 | C8: =COUNTIFS($A$18:$A$85,"Principal",$C$18:$C$85,A8) -> 2
A9: China | B9: =COUNTIFS($A$18:$A$85,"Coautor",$C$18:$C$85,A9) -> 9 | C9: =COUNTIFS($A$18:$A$85,"Principal",$C$18:$C$85,A9) -> 2
A10: Estados Unidos | B10: =COUNTIFS($A$18:$A$85,"Coautor",$C$18:$C$85,A10) -> 8 | C10: =COUNTIFS($A$18:$A$85,"Principal",$C$18:$C$85,A10) -> 3
A11: Brasil | B11: =COUNTIFS($A$18:$A$85,"Coautor",$C$18:$C$85,A11) -> 16 | C11: =COUNTIFS($A$18:$A$85,"Principal",$C$18:$C$85,A11) -> 12
A17: Tipo | B17: Autor | C17: País | D17: Artigo
A18: Principal | B18: Aliano Filho, Angelo | C18: Brasil | D18: A bi-objective mathematical model for integrated planning of sugarcane harvesting and transport operations
A19: Coautor | B19: Melo, Teresa | C19: Alemanha | D19: A bi-objective mathematical model for integrated planning of sugarcane harvesting and transport operations
A20: Coautor | B20: Pato, Margarida Vaz | C20: Portugal | D20: A bi-objective mathematical model for integrated planning of sugarcane harvesting and transport operations
A21: Principal | B21: Aguayo, Maichel M. | C21: Chile | D21: A branch-and-price approach for a biomass feedstock logistics supply chain design problem
A22: Coautor | B22: Sarin, Subhash C. | C22: Estados Unidos | D22: A branch-and-price approach for a biomass feedstock logistics supply chain design problem
A23: Coautor | B23: Cundiff, John S. | C23: Estados Unidos | D23: A branch-and-price approach for a biomass feedstock logistics supply chain design problem
A24: Principal | B24: da Silva, Aneirson Francisco | C24: Brasil | D24: A Fuzzy Goal Programming model for solving aggregate production-planning problems under uncertainty: A case study in a Brazilian sugar mill
A25: Coautor | B25: Marins, Fernando Augusto Silva | C25: Brasil | D25: A Fuzzy Goal Programming model for solving aggregate production-planning problems under uncertainty: A case study in a Brazilian sugar mill
A26: Principal | B26: de Paiva, Rafael Piatti Oiticica | C26: Brasil | D26: A hierarchical supply chain model for the sugar–alcohol energy sector with robust optimization analysis
A27: Coautor | B27: Rocco, Cleber D. | C27: Brasil | D27: A hierarchical supply chain model for the sugar–alcohol energy sector with robust optimization analysis
A28: Coautor | B28: Morabito, Reinaldo | C28: Brasil | D28: A hierarchical supply chain model for the sugar–alcohol energy sector with robust optimization analysis
... A85: Coautor | B85: Hosseininezhad, Seyed Javad | C85: Irã | D85: Designing a hub location model in a bagasse-based bioethanol supply chain network in Iran (case study: Iran sugar industry)

Sheet Publicações país aplicação
A1: País aplicação | B1: Publicações
A2: Não especificado | B2: =COUNTIFS('Base Artigos'!$I$2:$I$24,'Publicações país aplicação'!A2) -> 2
A3: Síria | B3: =COUNTIFS('Base Artigos'!$I$2:$I$24,'Publicações país aplicação'!A3) -> 1
A4: Irã | B4: =COUNTIFS('Base Artigos'!$I$2:$I$24,'Publicações país aplicação'!A4) -> 2
A5: China | B5: =COUNTIFS('Base Artigos'!$I$2:$I$24,'Publicações país aplicação'!A5) -> 2
A6: Estados Unidos | B6: =COUNTIFS('Base Artigos'!$I$2:$I$24,'Publicações país aplicação'!A6) -> 4
A7: Brasil | B7: =COUNTIFS('Base Artigos'!$I$2:$I$24,'Publicações país aplicação'!A7) -> 12

Sheet Análise
A1: Authors | B1: Title | C1: DOI | D1: Link | E1: Problema | F1: ART-Abordagem | G1: Abordagem de modelagem | H1: ART-Técnicas | I1: Técnicas de resolução | J1: ART-Etapa | K1: Etapa da Cadeia produtiva | L1: ART-Plataf | M1: Plataforma resolução | N1: ART-Objetivo | O1: ART-Incerteza | P1: Função Objetivo | Q1: ART-Decisão | R1: Nível de decisão | S1: Obs.
A2: Aliano Filho A.; Melo T.; Pato M.V. | B2: A bi-objective mathematical model for integrated planning of sugarcane harvesting and transport operations | C2: 10.1016/j.cor.2021.105419 | D2: https://www.scopus.com/inward/record.uri?eid=2-s2.0-85107960409&doi=10.1016%2fj.cor.2021.105419&partnerID=40&md5=382589458131fe6684852de077af5cfd | E2: - O objetivo é desenvolver um plano tático para a implantação de equipamentos de colheita e transporte que defina os períodos para a execução das operações de colheita nos campos de cana-de-açúcar e o tipo de máquinas de colheita e veículos de transporte rodoviário a serem operados | F2: MINLP-MO | G2: - bi-objective mixed-integer non-linear programming - mixed-integer non-linear programming (MINLP) | H2: - Descrever multiobjetivo conflitante | I2: - Progressive Bounded Constraint (PBC) - Linearização - Soluções ótimas de Pareto são identificadas pelo método Progressive Bounded Constraint que é estendido ao problema em questão - Técnicas de linearização ? - Soluções lexicográficas ? - Branch-and-Bound ? | K2: Planejamento integrado colheita e transporte para planejamento multiperíodo | M2: - CPLEX - JuMP modeling language and embedded in the Julia programming language | N2: - Minimizar custo total de colheita e transporte - Minimizar o tempo total de colheita | P2: Bi-objetivo - Minimizar o custo total de colheita e transporte - Minimizar o tempo total de colheita | R2: Tático (temporada de colheita abril-dezembro) | S2: Falar deste artigo, pois fez uma busca na literatura, não uma revisão sistemática, mas para entender o tema | U2: Utilizar na referência da revisão sistemática
A3: Aguayo M.M.; Sarin S.C.; Cundiff J.S. | B3: A branch-and-price approach for a biomass feedstock logistics supply chain design problem | C3: 10.1080/24725854.2019.1589656 | D3: https://www.scopus.com/inward/record.uri?eid=2-s2.0-85066629282&doi=10.1080%2f24725854.2019.1589656&partnerID=40&md5=5698914ef7199ea4133fce1b173a01eb | E3: - Problema de localização e instalações multiperíodo - Problema de dimensionamento de lote capacitado de item único com instalações paralelas (CLSP-PF) e um problema de fluxo de rede - Neste artigo, abordamos esse problema e, em particular, focamos no design de uma cadeia de suprimentos de logística de matéria-prima econômica encontrada durante a produção de etanol à base de switchgrass (capim-rabo-de-raposa). - Verifica número de instalações de armazenamento (centros de distribuição e produtores rurais) a serem incluídos na cadeia de armazenamento e dimensiona o transporte até a usina de bioenergia - Restrições de localização e dimensionamento de lote | F3: MILP | G3: - Mixed-integer program | I3: - branch-and-price - Geração do limite inferior com heurística? - Dual stabilization | K3: Transporte de capim-rabo-de-raposa até a usina de bioenergia | M3: CPLEX | N3: - Minimizar custo total | P3: - captura nosso objetivo de minimizar o custo total incorrido pela propriedade dos conjuntos de equipamentos de carga e tratores-reboques, instalação de SSLs, mobilização de equipamentos, embarque de biomassa de SSLs para a usina de bioenergia e instalação de conjuntos de equipamentos de carga | T3: Remover?
A4: da Silva A.F.; Marins F.A.S. | B4: A Fuzzy Goal Programming model for solving aggregate production-planning problems under uncertainty: A case study in a Brazilian sugar mill | C4: 10.1016/j.eneco.2014.07.005 | D4: https://www.scopus.com/inward/record.uri?eid=2-s2.0-84907853897&doi=10.1016%2fj.eneco.2014.07.005&partnerID=40&md5=b6cb58527aec159e6fa6e141369652a7 | E4: - Problema e planejamento de produção agregado - Previsão de cana a ser colhida por fornecedor e a quantidade de cana a ser moída - Determina a quantidade de produtos a ser produzida em cada processo industrial - Custo de transporte do produto final para o cliente - O Modelo FGP retrata o processo de produção abrangente de açúcar, etanol, melaço e derivados, e considera as incertezas envolvidas na produção de etanol e açúcar. As tomadas de decisão, relacionadas às fases agrícola e logística, foram consideradas em um horizonte de planejamento semanal para incluir toda a temporada de colheita e os períodos entre as colheitas. A pesquisa forneceu resultados interessantes sobre decisões nas etapas agrícolas de corte, carregamento e transporte para fornecedores de cana-de-açúcar e, especialmente, nas decisões de moagem, cuja escolha do processo de produção inclui armazenamento e distribuição logística. | F4: GP-FL | G4: - Fuzzy Goal Programming model (FGP) | I4: - Método exato, diretamente no SOLVER - Programação por metas ? - Incertezas ? | K4: - Planejamento agregado - Integração das fases agrícola, industrial e logística em um modelo único, para apoiar a tomada de decisões durante as safras e períodos entre safras. - Fornecimento de matéria prima, transporte e produção industrial | M4: - software GAMS - General Algebraic Modeling System, versão 24.2.1, enquanto o Solver CPLEX 12.6 foi utilizado para encontrar uma solução ótima para o modelo | N4: - Maximizar a produção total de açúcar cristal - Maximizar a produção total de açúcar VVHP - Maximizar a produção total de açúcar VHP - Maximizar a produção total de etanol - Minimizar os custos totais de armazenamento - Minimizar os custos totais de transporte de matéria-prima dos fornecedores - Minimizar os custos totais de matéria-prima dos fornecedores - Minimizar os custos totais de processamento de matéria-prima - Minimizar os custos totais de distribuição aos clientes | P4: Multiobjetivo - Minimizar os custos de cada fase agroindustrial --Fornecimento de matéria-prima -- Transporte de cana-de-açúcar -- Processo de produção - Minimizar o custo total do estoque - Minimizar o custo total de distribuição dos produtos aos clientes - Maximizar a produção: --Açúcar Cristal --Açúcar VHP --Açúcar VVHP --Produção de etanol | R4: Estratégico ? Uma safra (período t (colheita e entre colheitas ou 52 semanas);
A5: de Paiva R.P.O.; Rocco C.D.; Morabito R. | B5: A hierarchical supply chain model for the sugar–alcohol energy sector with robust optimization analysis | C5: 10.1111/itor.12909 | D5: https://www.scopus.com/inward/record.uri?eid=2-s2.0-85096878415&doi=10.1111%2fitor.12909&partnerID=40&md5=f838f5685e6d8194fa58d6a2b2db6313 | E5: - O primeiro nível hierárquico do modelo da cadeia de suprimentos corresponde ao planejamento agregado da colheita, considerando todas as usinas da sociedade cooperativa, com foco nas principais decisões mensais sobre o mix de produção, armazenamento e políticas de vendas da sociedade cooperativa. No segundo nível, as decisões são menos agregadas, considerando o planejamento semanal da colheita e as configurações industriais de cada usina no sistema cooperativo para atender à demanda potencial do produto (açúcar, etanol e melaço) definida no primeiro nível do modelo. - 10 moinhos, 12 produtos, 12 meses, 25 semanas e 24 processos industriais. | F5: MILP-RO | G5: - Programação linear inteira mista com otimização robusta - Modelo linear - Abordagem de otimização robusta com dois parâmetros de incerteza (1º preço nominal dos produtos fabricados e vendidos; 2º matriz de rendimentos industrial) | I5: - Solver | K5: - Transporte, colheita, produção industrial e venda | M5: CPLEX | N5: -Maximizar lucro de venda dos produtos - Maximizar receitas | P5: Multiobjetivo - Modelo 1: maximizar o lucro de venda de todos os produtos de todas as fábricas e a energia exportada ao longo do horizonte de planejamento considerando custos de produção e armazenagem - Maximizar a margem de contribuição da cooperativa (todas as usinas) - Maximizar a margem de contribuição de cada usina ** - O V Ppt é um parâmetro de marketing que está dentro da função objetivo do PASUC/L1 e corresponde aos preços do açúcar e dos álcoois (índice p por produto) sujeitos aos derivativos das flutuações do mercado ao longo do tempo (índice t para mês), cuja análise de incerteza é criticamente importante para a lucratividade do negócio - O parâmetro Apkw é o matriz de rendimentos industriais em PASUC/L2. Representa o rendimento do produto p fabricado a partir do processo k na usina na semana w. A indexação por períodos (índice w para semana) traz para o modelo as características agrícolas e industriais, que variam ao longo da temporada de colheita, como o açúcar total recuperável (ATR) (parâmetro T RSuw) na usina u, o teor de fibra da cana-de-açúcar do fornecedor m (Fibermw) e o tempo útil de operação da moagem (ÿw) ao longo das semanas do horizonte de planejamento. - A função objetivo (1) do PASUC/L1 maximiza o lucro para o máximo esperado demanda (Dpt) da venda de todos os produtos produzidos em todas as fábricas ao longo dos períodos no horizonte de planejamento, considerando também os custos de produção e aqueles derivados da política de armazenagem - A função objetivo (22) maximiza a receita da venda de todos os produtos e energia exportados para a rede de um moinho associado à cooperativa do moinho, deduzindo os custos de produção e logística | R5: Estratégico e Tático | S5: - Utilizou conjunto de dados reais, diferente de Paiva Morabito 2014 que teve objetivo de validar os modelos - Descreve operação básica da indústria com uma figura simples - Diagrama de processo com base no Paiva e Morabito 2013
A6: de Paiva R.P.O.; Morabito R. | B6: An optimization model for the aggregate production planning in alcohol and sugar mills; [Um modelo de otimização para o planejamento agregado da produção em usinas de açúcar e álcool] | C6: 10.1590/s0104-530x2007000100004 | D6: https://www.scopus.com/inward/record.uri?eid=2-s2.0-34547371168&doi=10.1590%2fs0104-530x2007000100004&partnerID=40&md5=27f18fb49bfbcfa7f8242dfa7066497e | E6: - Este modelo se baseia nos modelos clássicos de seleção de processos e dimensionamento de lotes para representar o sistema de produção de açúcar, álcool e melaço, incluindo decisões da etapa agrícola, das fases de corte, carregamento e transporte de cana e, principalmente, decisões de moagem, escolha do processo produtivo e estoque dos produtos finais. As decisões são tomadas em períodos semanais e o horizonte de planejamento são as semanas de safra. | G6: - Modelo combinado de seleção de processo e dimensionamento de lotes | I6: -Solver | K6: - Quanto comprar de cana, corte, carregamento, transporte, produção industrial e estoque | M6: Linguagem de modelagem GAMS no CPLEX | P6: - maximizar a margem de contribuição agroindustrial de produção dos produtos p, por meio dos processos k, da matéria-prima m, do tipo de transporte da matéria-prima f e do local de estoque e, em todos os períodos t - Maximizar a margem de contribuição - O problema consiste em determinar o quanto produzir de cada produto em cada processo, de maneira a minimizar os custos de produção, sujeito às restrições de limitação de recursos e atendimento da demanda | R6: Estratégico ? - uma safra | S6: macro-operações envolvidas no processo de produção de uma usina (pesagem, estocagem, lavagem, preparo/moagem, clarificação do caldo, evaporação, cozimento/turbinação) e de uma destilaria (fermentação/centrifugação, destilação). Também podemos perceber as macro-perdas envolvidas na produção de açúcar e álcool (perdas na água de lavagem, no bagaço, na torta, na fermentação, na vinhaça e perdas indeterminadas) | T6: Utilizar como base para o modelo | U6: São iguais | V6: Remover duplicado
A7: de Paiva R.P.O.; Morabito R. | B7: An optimization model for the aggregate production planning of a Brazilian sugar and ethanol milling company | C7: 10.1007/s10479-008-0428-9 | D7: https://www.scopus.com/inward/record.uri?eid=2-s2.0-64149125605&doi=10.1007%2fs10479-008-0428-9&partnerID=40&md5=7548dd3f373362d52f20ba43531f8c91 | E7: - o modelo proposto neste artigo visa utilizar uma perspectiva agregada de toda a cadeia de suprimentos agroindustrial para auxiliar os tomadores de decisão na seleção processos industriais utilizados na produção de açúcar, etanol e melaço, bem como na determinação das quantidades de cana-de-açúcar moída, na seleção de fornecedores de cana-de-açúcar e na determinação de fornecedores de transporte e as decisões de armazenagem relacionadas aos produtos finais. No estudo de caso que está sendo considerado, essas decisões são tomadas semanalmente e o horizonte de planejamento é toda a temporada de colheita da cana-de-açúcar (ou seja, 23 semanas). | F7: MILP | G7: -Programação inteira mista | I7: - Modelo combinado de seleção de processo e dimensionamento de lotes | K7: - Quanto comprar de cana, corte, carregamento, transporte, produção industrial e estoque | M7: Linguagem de modelagem GAMS no CPLEX | N7: -Maximizar receita variável total de todos os setores agroindustriais e etapas da usina | P7: - A função objetivo (1) maximiza a receita variável total de todos os setores agroindustriais. etapas da usina. Esta função objetivo auxilia o tomador de decisão a determinar a quantidade de cana-de-açúcar moída, a seleção de fornecedores de cana-de-açúcar, a seleção de cana-de-açúcar fornecedores de transporte, a seleção do processo industrial utilizado na produção de açúcar, etanol e melaço e as decisões de armazenagem relacionadas aos produtos finais visando atingir a receita máxima em toda a temporada de colheita | R7: Estratégico ? - uma safra | T7: Utilizar como base para o modelo | U7: São iguais | V7: 669 mil unidades monetárias
A8: Li X.; Jin X.; Lu S.; Li Z.; Wang Y.; Cao J. | B8: Carbon-efficient production scheduling of a bioethanol plant considering diversified feedstock pelletization density: A case study | C8: 10.3390/PR8091189 | D8: https://www.scopus.com/inward/record.uri?eid=2-s2.0-85092094522&doi=10.3390%2fPR8091189&partnerID=40&md5=6ff1f4447942e7ccc373334ed5fdcc3a | E8: - O caso considera tanto a palha de milho quanto a palha de trigo como matérias-primas de biomassa, e adota duas técnicas de enfardamento para transformar as matérias-primas em fardos retangulares e redondos, respectivamente. A palha de milho, a palha de trigo e outros resíduos deixados após a colheita podem ser usados ​​para a produção de bioetanol durante todo o ano. - Este artigo apresenta um modelo específico de otimização de programação de produção com eficiência em carbono para a planta de bioetanol e propõe uma abordagem de otimização de objetivo duplo para demonstrar a eficácia em decisões flexíveis entre emissão de carbono e lucro. Os efeitos de diferentes matérias-primas de biomassa com densidade de peletização opcional e métodos de pré-tratamento na programação da produção são analisados. | F8: MILP-MO | G8: - mixed integer linear programming (MILP) - bi-objetivo | I8: -Solver - método ponderado por associação - Pareto | K8: - Produção de bioetanol - Aquisição de matéria-prima, embalagem e transporte da matéria até a usina de bioetanol - A usina de bioetanol adquire as matérias-primas dos fornecedores de acordo com a demanda de produção. (Suprimentos..) - custo de compra, armazenamento da matéria, transporte, pré-tratamento, armazenamento do produto intermediário e fermentação do etanol | M8: - LINGO | N8: -Maximizar o lucro total - Minimizar as emissões de carbono | P8: - bi-objetivo - O problema de programação da produção de biocombustível de etanol acima mencionado avalia dois objetivos principais de otimização, eles são o lucro total e a emissão de carbono. Como esses dois aspectos são medidos por escalas diferentes, um modelo de otimização de objetivo duplo é introduzido, que usa o método de ponderação de associação para resolver e, então, é otimizado simultaneamente - Primeiramente, o planejamento da produção e programação do transporte, armazenamento, pré-tratamento e fabricação de etanol da usina de bioetanol são totalmente considerados. Em segundo lugar, as emissões de carbono no processo de fabricação de etanol são integradas ao modelo para formar um modelo de otimização de objetivo duplo que otimiza simultaneamente o plano de produção e as emissões de carbono | S8: - Para lidar com esse problema, este artigo primeiro estabelece um modelo MILP de programação do processo de produção de bioetanol, considerando o trade-off entre emissões de carbono e lucros. Em segundo lugar, com base na influência de diferentes esquemas de pré-tratamento no rendimento de bioetanol no processo de produção de bioetanol, a influência dos esquemas de pré-tratamento no lucro total com condições de demanda variáveis é estudada. Finalmente, uma abordagem de otimização de objetivo duplo com base na associação ponderada é aplicada para equilibrar quantitativamente os efeitos da emissão de carbono na programação da produção e, com base nisso, fornece uma ferramenta com eficiência de carbono para projetar a programação da produção da planta de bioetanol. | T8: planta de bioetanol, palha de milho e de trigo
A9: Saadati M.; Hosseininezhad S.J. | B9: Designing a hub location model in a bagasse-based bioethanol supply chain network in Iran (case study: Iran sugar industry) | C9: 10.1016/j.biombioe.2019.01.013 | D9: https://www.scopus.com/inward/record.uri?eid=2-s2.0-85061054948&doi=10.1016%2fj.biombioe.2019.01.013&partnerID=40&md5=41d1fc458d170af3a2034fb3fc7fc0de | E9: - o estudo atual propõe um modelo de programação linear inteira mista multiobjetivo para localizar instalações de hub na rede da cadeia de suprimentos de bioetanol à base de bagaço. A metodologia proposta é capaz de determinar o número ideal de locais, a capacidade das instalações, o modo de transporte apropriado, o fluxo de material entre cada par de nós e o planejamento da produção em diferentes períodos. Para ilustrar a aplicação do modelo desenvolvido, um estudo de caso do Irã é conduzido e o desempenho do modelo desenvolvido é avaliado usando dados do mundo real relacionados à indústria açucareira do Irã. - Este artigo desenvolve um modelo de hub-and-spoke para uma planta de beneficiamento de bagaço rede da cadeia de suprimentos de bioetanol. - A rede é composta por cinco escalões: centros de abastecimento, centros de pré-processamento, biorrefinarias, instalações de hub e centros de demanda. | F9: MILP-MO | G9: - mixed integer linear programming (MILP) - multi-objetivo | I9: - Soluções Pareto-ótimas são exploradas em vez de soluções ótimas e posteriormente, o tradeoff entre duas funções objetivo - O trade-off entre a minimização dos custos totais e emissão de CO2 e o diagrama de Pareto resultante do método e-constraint - é feita uma análise de sensibilidade em dois dos parâmetros do modelo (custo de importação, estabelecimento do hub) | J9: AGR-IND-COM | K9: - Neste artigo, é apresentado um modelo MILP, incluindo alocação de localização de instalações, planejamento de distribuição e planejamento de produção. - Determinar o número ideal de locais, capacidade das instalações, modo de transporte adequado, planejamento de produção e importação e fluxo de materiais entre componentes da cadeia de suprimentos em diferentes períodos de tempo. | M9: Linguagem de modelagem GAMS no CPLEX | N9: -Minimizar custos transporte, instalação, importação de matéria-prima, produção, estoque -Minimizar emissões de carbono | P9: - multi-objetivo - MILP proposto para minimizar custos e redução de CO2 simultâneamente - O objetivo do planejamento é minimizar o custo total e a emissão de CO2 e rede de cadeia de fornecimento de bioetanol à base de bagaço simultaneamente | R9: - Estratégica e tática - O modelo proposto aborda as seguintes decisões estratégicas e táticas da cadeia de suprimentos: (1) decisões estratégicas de nível estratégico que tratam da determinação do número, capacidade e localização de centros de pré-processamento, biorrefinarias e hubs. As decisões em níveis táticos são atribuídas à programação de produção, como quantidade de produção, nível de estoque e número de materiais transportados entre diferentes níveis da cadeia em diferentes períodos.
A10: de Paiva R.P.O.; Morabito R. | B10: Hierarchical production planning for sugarcane milling companies: Robust optimization model; [Planejamento hierárquico da produção em usinas de açúcar e álcool: Modelagem de otimização robusta] | C10: 10.1590/S0103-65132013005000032 | D10: https://www.scopus.com/inward/record.uri?eid=2-s2.0-84905180400&doi=10.1590%2fS0103-65132013005000032&partnerID=40&md5=11fdc50c66ee89ce72213dd34c6ce6ec | E10: - Recentemente Paiva (2009) e Paiva e Morabito (2012) apresentaram um modelo de otimização determinístico para o problema de planejamento agregado da produção em usinas cooperadas do setor sucroenergético. Esta modelagem, denominada PASUC (Planejamento Agregado de Safra em Usinas Cooperadas do Setor Sucroenergético), considera a relação hierárquica existente entre o planejamento anual da cooperativa e o planejamento tático de safra das usinas cooperadas, propiciando a análise integrada do planejamento de safra em um grupo de usinas. | F10: MILP-RO | G10: - Programação linear e programação linear inteira mista - modelo de otimização robusta com incerteza | K10: -No nível de decisão da cooperativa (PASUC/N1), um modelo de programação linear multiproduto, dois estágios, dinâmico, capacitado, com horizonte de planejamento anual e agregação temporal mensal determina a quantidade e o mix de produção (PUput) das usinas, a política de estoque (Ipet) e a política de atendimento da demanda (Dpt) - No nível de decisão de cada usina cooperada (PASUC/N2), um modelo de programação inteira mista multiproduto, monoestágio, multiprocesso, dinâmico, capacitado, com horizonte de planejamento do período de moagem (aproximadamente 6 meses) e agregação temporal semanal combina decisões de dimensionamento e sequenciamento dos lotes de produção para o atendimento das metas do primeiro nível hierárquico | M10: Linguagem de modelagem GAMS no CPLEX | N10: -Maximizar a margem de contribuição ao lucro da produção de todos os produtos em todas as usinas e em todos os períodos - Maximizar a margem de contribuição da produção por meio dos processos, da matéria-prima e do tipo de transporte da matéria-prima, em todos os períodos ** incluindo as incertezas do preço de venda e da eficiência industrial | P10: - Essas variáveis devem ser calculadas de forma que a margem de contribuição do grupo seja maximizada -O objetivo é obter um plano tático de safra que proporcione a máxima margem de contribuição, respeitando as restrições de previsão de safra, capacidade de transporte, capacidade de estoque, fluxo de caixa positivo e necessidade de energia térmica e elétrica nos processos industriais. | Q10: -Tático - Operacional | R10: - Tático e Operacional | S10: Cita trabalhos anteriores deles de 2011
A11: Kim S.; Kim S. | B11: Hybrid simulation framework for the production management of an ethanol biorefinery | C11: 10.1016/j.rser.2021.111911 | D11: https://www.scopus.com/inward/record.uri?eid=2-s2.0-85119432925&doi=10.1016%2fj.rser.2021.111911&partnerID=40&md5=1a15026c6c014b2223443a4f97c6f886 | E11: - neste estudo, propomos uma estrutura de simulação híbrida para o planejamento de produção sustentável de uma refinaria de biocombustível para sua produção de etanol à base de grãos. E este estudo será a primeira tentativa de avaliar o desempenho econômico de toda a cadeia de suprimentos, desde a plantação de matéria-prima para biocombustíveis até a produção de etanol. | I11: -Para incorporar as interações dinâmicas e contínuas dentro de uma instalação, adotamos simulação baseada em agentes (ABS - agent-based simulation) neste estudo. ABS é um paradigma de simulação contínua equipado com algoritmos de inteligência artificial (IA) para tomar decisões sobre múltiplos agentes - Existem oito operações principais em uma refinaria, e as operações estão intimamente conectadas entre si. Modelamos as interações entre as operações e as atividades de transporte entre fazendas de matéria-prima e uma refinaria por meio do ABS, usando o software AnyLogic® para a modelagem. - adotamos o OptQuest®, que é um mecanismo de otimização meta-heurística, para encontrar uma taxa de produção apropriada com o custo operacional mínimo - Para validação do modelo, comparamos os rendimentos simulados de milho com os rendimentos medidos de 2015 a 2018. Para avaliar a calibração e validação do modelo, calculamos o viés percentual (PBIAS), o erro quadrático médio (RMSE) e o coeficiente de correlação de determinação de Pearson (R2 ). | M11: - Para uma estimativa precisa da distância de viagem entre fazendas e uma refinaria, usamos o módulo GIS no AnyLogic® AnyLogic | S11: Não faz simulação, excluir
A12: Corsano G.; Fumero Y.; Montagna J.M. | B12: Integrated decision making for the optimal bioethanol supply chain | C12: 10.1016/j.enconman.2014.04.090 | D12: https://www.scopus.com/inward/record.uri?eid=2-s2.0-84910075619&doi=10.1016%2fj.enconman.2014.04.090&partnerID=40&md5=a1d95054598a77fc254a92826334e881 | E12: -O modelo proposto neste trabalho determina simultaneamente a estrutura de uma cadeia de suprimentos de três escalões (locais de matéria-prima, instalações de produção e zonas de clientes), o projeto de cada planta instalada e considerações operacionais por meio de campanhas de produção. A produção de levedura é considerada para reduzir o impacto ambiental negativo causado por resíduos de bioetanol. | F12: MILP | G12: - mixed integer linear programming (MILP) - Their approach establishes the optimal plant configuration (unit dimensions, units duplication) and the production planning using mixed product campaigns (MPC) (number of batches of each product in the campaign and its sequencing) | I12: -Solver | K12: -compreende três escalões: matéria-prima locais de materiais, instalações de produção de etanol/levedura e zonas de clientes. - Cada planta instalada pode produzir os três produtos: levedura torula, etanol e levedura de padeiro, e eles têm as etapas de processo | M12: -GAMS | N12: - Maximizar o lucro | P12: - A medida de desempenho é maximizar o lucro líquido calculado como os benefícios das vendas menos o custo anual total, dado por instalação de plantas, investimento, produção e transporte custos - A função objetivo é a maximização do lucro líquido anual benefício (ANB) dado pela receita de vendas menos o total anual custo que considera o custo de instalação, o custo de investimento e o custo de transporte, descritos a seguir: - receita de vendas - custo de instalação: custo de instalação da planta - custo de investimento: coeficientes de custo adequados para o estágio j, planta f, para levar em conta a amortização, um fator de encargo de capital no horizonte temporal - custo de transporte: transporte de matérias-primas e produtos - custo de cana-de-açúcar: Este custo abrange o cultivo da cana, a colheita, o transporte, fertilização e trabalho de campo relacionado - custo operacional: considera um custo por tonelada de produto produzido em cada planta - a) O projeto do SC: (i) localização das unidades de produção; (ii) fornecimento de melaço de cada planta de cana-de-açúcar; (iii) etanol e produção de leveduras em cada planta instalada; e, (iv) matéria-prima fluxos de materiais e produtos entre nós SC. b) O projeto de cada uma das plantas instaladas: c) O planejamento detalhado da produção de cada unidade de etanol/planta de levedura | S12: Outro do Corsano MINLP
